Workbook

Sheet FACTSHEET
A1: FACTSHEET - GLOBAL ESG-BASED PORTFOLIO PERFORMANCE AMONG MAJOR FRENCH COMPANIES (2020–2024)
A3: Region | B3: Western Europe | C3: Ecology is important, but social and governance factors also play a crucial role. It makes little sense to promote environmental progress while degrading workers’ labour conditions, and several studies have shown that having more women on boards leads to better decision-making. Therefore, after careful reflection, we decided to focus on the overall ESG score, which combines environmental, social, and governance dimensions, rather than considering only the environmental aspect of the assets. We combined this ESG approach with a territorial criterion to support French companies with higher market capitalizations, using the CAC 40 as the parent index for comparison. Consequently, we selected the 29 largest companies by market capitalization and built portfolios strictly according to their ESG scores in order to study their returns and dynamics over the period from January 1, 2020, to January 1, 2024. Given the restricted sample size and the fact that ESG performance was our sole selection criterion, the resulting portfolios are somewhat unbalanced and highly dependent on the movements of certain assets. Nevertheless, it remains interesting to analyze their performance in relation to the sustainability of the companies.
A4: Country | B4: France
A5: Parent Index | B5: CAC 40
A6: #Constituents | B6: 29
A7: Start Date | B7: 43831
A8: End Date | B8: 45292
A9: Screening | B9: GLOBAL ESG
A10: Frequency | B10: Daily
A11: Currency | B11: EUR
A13: PORTFOLIO'S COMPOSITION
H15: AVERAGE DAILY RETURN AND RISK OF OUR 4 PORTFOLIOS AND PARENTING INDEX
A16: PORTFOLIO | B16: COMPANY | C16: MARKET CAP | D16: SECTOR | F16: ESG
I17: 2020 | K17: 2021 | M17: 2022 | O17: 2023
A18: PTF 10% | B18: Schneider Electric S.E. | C18: 122.95 | D18: Specialty Industrial Machinery | F18: =VLOOKUP(B18,Table3[[COMPANY NAME]:[GLOBAL ESG]],14,0) -> 9.4 | I18: RETURN | J18: RISK | K18: RETURN | L18: RISK | M18: RETURN | N18: RISK | O18: RETURN | P18: RISK | Q18: SHARPE
B19: Kering SA | C19: 29.1 | D19: Luxury Goods | F19: =VLOOKUP(B19,Table3[[COMPANY NAME]:[GLOBAL ESG]],14,0) -> 10.7 | H19: AVG PTF 10% | I19: 0.00041374898 | J19: 0.023547358 | K19: 0.0011761945 | L19: 0.014092721 | M19: -0.001159725 | N19: 0.019574992 | O19: 6.9683905e-05 | P19: 0.013976509 | Q19: -0.073496684
B20: Capgemini SE | C20: 21.24 | D20: Information Technology Services | F20: =VLOOKUP(B20,Table3[[COMPANY NAME]:[GLOBAL ESG]],14,0) -> 7.6 | H20: AVG PTF 20% | I20: 0.00077324801 | J20: 0.019673415 | K20: 0.0017493279 | L20: 0.013069733 | M20: -0.00044462558 | N20: 0.020223077 | O20: 0.00080645849 | P20: 0.013868085 | Q20: 0.54972047
H21: AVG PTF 50% | I21: 0.00061846363 | J21: 0.019125869 | K21: 0.0015892455 | L21: 0.012013791 | M21: -0.00036148371 | N21: 0.018827885 | O21: 0.00068572294 | P21: 0.012963744 | Q21: 0.49889449
A22: PTF 20% | B22: Hermès International Société en commandite par actions | C22: 213.76 | D22: Luxury Goods | F22: =VLOOKUP(B22,Table3[[COMPANY NAME]:[GLOBAL ESG]],14,0) -> 12.7 | H22: AVG PTF 100% | I22: 0.00036325297 | J22: 0.019728774 | K22: 0.0013431895 | L22: 0.011267582 | M22: -0.00028248958 | N22: 0.017226774 | O22: 0.00062251281 | P22: 0.011719348 | Q22: 0.38903477
B23: Schneider Electric S.E. | C23: 122.95 | D23: Specialty Industrial Machinery | F23: =VLOOKUP(B23,Table3[[COMPANY NAME]:[GLOBAL ESG]],14,0) -> 9.4 | H23: CAC40 | I23: -9.0463382e-05 | J23: 0.020196029 | K23: 0.0010372077 | L23: 0.0092290634 | M23: -0.00029089428 | N23: 0.01370195 | O23: 0.00060548674 | P23: 0.0085918956
B24: Dassault Systèmes SE | C24: 35.37 | D24: Software - Application | F24: =VLOOKUP(B24,Table3[[COMPANY NAME]:[GLOBAL ESG]],14,0) -> 12.8
B25: Kering SA | C25: 29.1 | D25: Luxury Goods | F25: =VLOOKUP(B25,Table3[[COMPANY NAME]:[GLOBAL ESG]],14,0) -> 10.7
B26: Compagnie Générale des Établissements Michelin Société en commandite par actions | C26: 21.79 | D26: Automobiles & Auto Parts | F26: =VLOOKUP(B26,Table3[[COMPANY NAME]:[GLOBAL ESG]],14,0) -> 11.5
B27: Capgemini SE | C27: 21.24 | D27: Information Technology Services | F27: =VLOOKUP(B27,Table3[[COMPANY NAME]:[GLOBAL ESG]],14,0) -> 7.6
A30: PTF 50% | B30: LVMH Moët Hennessy - Louis Vuitton, Société Européenne | C30: 246.65 | D30: Luxury Goods | F30: =VLOOKUP(B30,Table3[[COMPANY NAME]:[GLOBAL ESG]],14,0) -> 13.8
B31: Hermès International Société en commandite par actions | C31: 213.76 | D31: Luxury Goods | F31: =VLOOKUP(B31,Table3[[COMPANY NAME]:[GLOBAL ESG]],14,0) -> 12.7
B32: Schneider Electric S.E. | C32: 122.95 | D32: Specialty Industrial Machinery | F32: =VLOOKUP(B32,Table3[[COMPANY NAME]:[GLOBAL ESG]],14,0) -> 9.4
B33: EssilorLuxottica Société anonyme | C33: 119.71 | D33: Medical Instruments & Supplies | F33: =VLOOKUP(B33,Table3[[COMPANY NAME]:[GLOBAL ESG]],14,0) -> 16.7
B34: L'Air Liquide S.A. | C34: 101.14 | D34: Specialty Chemicals | F34: =VLOOKUP(B34,Table3[[COMPANY NAME]:[GLOBAL ESG]],14,0) -> 13.8
B35: BNP Paribas SA | C35: 85.54 | D35: Banks - Regional | F35: =VLOOKUP(B35,Table3[[COMPANY NAME]:[GLOBAL ESG]],14,0) -> 17.2
B36: AXA SA | C36: 82.42 | D36: Insurance - Diversified | F36: =VLOOKUP(B36,Table3[[COMPANY NAME]:[GLOBAL ESG]],14,0) -> 16.3
B37: Danone S.A. | C37: 48.5 | D37: Packaged Foods | F37: =VLOOKUP(B37,Table3[[COMPANY NAME]:[GLOBAL ESG]],14,0) -> 17.6
B38: Société Générale Société anonyme | C38: 41.13 | D38: Banks - Regional | F38: =VLOOKUP(B38,Table3[[COMPANY NAME]:[GLOBAL ESG]],14,0) -> 15.4
B39: Dassault Systèmes SE | C39: 35.37 | D39: Software - Application | F39: =VLOOKUP(B39,Table3[[COMPANY NAME]:[GLOBAL ESG]],14,0) -> 12.8
B40: Legrand SA | C40: 34.36 | D40: Electrical Equipment & Parts | F40: =VLOOKUP(B40,Table3[[COMPANY NAME]:[GLOBAL ESG]],14,0) -> 15 | H40: MATRICE CORRELATION RETURN PTF | O40: BETA ANALYSIS
B41: Kering SA | C41: 29.1 | D41: Luxury Goods | F41: =VLOOKUP(B41,Table3[[COMPANY NAME]:[GLOBAL ESG]],14,0) -> 10.7
B42: Compagnie Générale des Établissements Michelin Société en commandite par actions | C42: 21.79 | D42: Automobiles & Auto Parts | F42: =VLOOKUP(B42,Table3[[COMPANY NAME]:[GLOBAL ESG]],14,0) -> 11.5 | I42: AVG PTF 10% | J42: AVG PTF 20% | K42: AVG PTF 50% | L42: AVG PTF 100% | M42: CAC40 | P42: 2020 | Q42: 2021 | R42: 2022 | S42: 2023 | T42: 4 years
B43: Capgemini SE | C43: 21.24 | D43: Information Technology Services | F43: =VLOOKUP(B43,Table3[[COMPANY NAME]:[GLOBAL ESG]],14,0) -> 7.6 | H43: AVG PTF 10% | I43: 1 | O43: PTF 10% | P43: 0.88657356 | Q43: 0.99119506 | R43: 0.95083379 | S43: 0.98441281 | T43: 0.92437413
H44: AVG PTF 20% | I44: 0.74913146 | J44: 1 | O44: PTF 20% | P44: 0.71526424 | Q44: 0.8544547 | R44: 0.90603183 | S44: 0.94530633 | T44: 0.80152073
H45: AVG PTF 50% | I45: 0.86311815 | J45: 0.80542131 | K45: 1 | O45: PTF 50% | P45: 0.73059643 | Q45: 0.85597723 | R45: 0.88756968 | S45: 0.9278718 | T45: 0.8035161
...

Sheet CALCULATION on ptf's return
A1: RETURN OF THE AVG CAP PER TRESHHOLD
A2: year | B2: AVG PTF 10% | C2: AVG PTF 20% | D2: AVG PTF 50% | E2: AVG PTF 100% | F2: CAC40
A3: 2020 | B3: ='CALCULATION of avg returns'!AO3 -> 0.0034409246 | C3: ='CALCULATION of avg returns'!AP3 -> 0.0047264787 | D3: ='CALCULATION of avg returns'!AQ3 -> 0.0024300989 | E3: ='CALCULATION of avg returns'!AR3 -> 0.0022529756 | F3: ='CALCULATION of avg returns'!AS3 -> -0.0027648344 | I3: nb
A4: 2020 | B4: ='CALCULATION of avg returns'!AO4 -> -0.014996211 | C4: ='CALCULATION of avg returns'!AP4 -> -0.011627226 | D4: ='CALCULATION of avg returns'!AQ4 -> -0.0095501567 | E4: ='CALCULATION of avg returns'!AR4 -> -0.0068546499 | F4: ='CALCULATION of avg returns'!AS4 -> -0.0065625839 | H4: 2020 | I4: =COUNTIF(A3:A1028,H4) -> 257 | N4: MATRICE CORRELATION RETURN PTF
A5: 2020 | B5: ='CALCULATION of avg returns'!AO5 -> 0.0065211907 | C5: ='CALCULATION of avg returns'!AP5 -> 0.0091373499 | D5: ='CALCULATION of avg returns'!AQ5 -> 0.006026401 | E5: ='CALCULATION of avg returns'!AR5 -> 0.0022882443 | F5: ='CALCULATION of avg returns'!AS5 -> 0.0075143781 | H5: 2021 | I5: =COUNTIF(A4:A1029,H5) -> 258
A6: 2020 | B6: ='CALCULATION of avg returns'!AO6 -> 0.0011779891 | C6: ='CALCULATION of avg returns'!AP6 -> 0.0051209456 | D6: ='CALCULATION of avg returns'!AQ6 -> 0.0046573057 | E6: ='CALCULATION of avg returns'!AR6 -> 0.0049696546 | F6: ='CALCULATION of avg returns'!AS6 -> -0.0045383333 | H6: 2022 | I6: =COUNTIF(A5:A1030,H6) -> 257 | O6: AVG PTF 10% | P6: AVG PTF 20% | Q6: AVG PTF 50% | R6: AVG PTF 100% | S6: CAC40
A7: 2020 | B7: ='CALCULATION of avg returns'!AO7 -> -0.0027036838 | C7: ='CALCULATION of avg returns'!AP7 -> 0.00075287032 | D7: ='CALCULATION of avg returns'!AQ7 -> 0.0037647384 | E7: ='CALCULATION of avg returns'!AR7 -> 0.0036687709 | F7: ='CALCULATION of avg returns'!AS7 -> 0.010276639 | H7: 2023 | I7: =COUNTIF(A6:A1031,H7) -> 254 | N7: AVG PTF 10% | O7: 1
A8: 2020 | B8: ='CALCULATION of avg returns'!AO8 -> -0.0028365234 | C8: ='CALCULATION of avg returns'!AP8 -> 6.4853787e-05 | D8: ='CALCULATION of avg returns'!AQ8 -> -0.00066091977 | E8: ='CALCULATION of avg returns'!AR8 -> -0.0006751001 | F8: ='CALCULATION of avg returns'!AS8 -> -0.00097113927 | G8: AVG daily RETURN(%) | I8: PTF 10% | J8: PTF 20% | K8: PTF 50% | L8: PTF 100% | M8: CAC40 | N8: AVG PTF 20% | O8: 0.74913146 | P8: 1
A9: 2020 | B9: ='CALCULATION of avg returns'!AO9 -> 0.0038641141 | C9: ='CALCULATION of avg returns'!AP9 -> 0.0024188894 | D9: ='CALCULATION of avg returns'!AQ9 -> 0.0016351339 | E9: ='CALCULATION of avg returns'!AR9 -> 0.0021838888 | F9: ='CALCULATION of avg returns'!AS9 -> -0.0016522098 | H9: 2020 | I9: =AVERAGEIF($A$3:$A$1028,$H9,B$3:B$1028) -> 0.00041374898 | J9: =AVERAGEIF($A$3:$A$1028,$H9,C$3:C$1028) -> 0.00077324801 | K9: =AVERAGEIF($A$3:$A$1028,$H9,D$3:D$1028) -> 0.00061846363 | L9: =AVERAGEIF($A$3:$A$1028,$H9,E$3:E$1028) -> 0.00036325297 | M9: =AVERAGEIF($A$3:$A$1028,$H9,F$3:F$1028) -> -9.0463382e-05 | N9: AVG PTF 50% | O9: 0.86311815 | P9: 0.80542131 | Q9: 1
A10: 2020 | B10: ='CALCULATION of avg returns'!AO10 -> 0.0017678921 | C10: ='CALCULATION of avg returns'!AP10 -> 0.0073361971 | D10: ='CALCULATION of avg returns'!AQ10 -> 0.006793159 | E10: ='CALCULATION of avg returns'!AR10 -> 0.0061206831 | F10: ='CALCULATION of avg returns'!AS10 -> -0.0063605685 | H10: 2021 | I10: =AVERAGEIF($A$3:$A$1028,$H10,B$3:B$1028) -> 0.0011761945 | J10: =AVERAGEIF($A$3:$A$1028,$H10,C$3:C$1028) -> 0.0017493279 | K10: =AVERAGEIF($A$3:$A$1028,$H10,D$3:D$1028) -> 0.0015892455 | L10: =AVERAGEIF($A$3:$A$1028,$H10,E$3:E$1028) -> 0.0013431895 | M10: =AVERAGEIF($A$3:$A$1028,$H10,F$3:F$1028) -> 0.0010372077 | N10: AVG PTF 100% | O10: 0.84369373 | P10: 0.74820415 | Q10: 0.92464751 | R10: 1
A11: 2020 | B11: ='CALCULATION of avg returns'!AO11 -> 0.0035921249 | C11: ='CALCULATION of avg returns'!AP11 -> 0.0074690129 | D11: ='CALCULATION of avg returns'!AQ11 -> 0.0051218501 | E11: ='CALCULATION of avg returns'!AR11 -> 0.0050870004 | F11: ='CALCULATION of avg returns'!AS11 -> 0.0052223644 | H11: 2022 | I11: =AVERAGEIF($A$3:$A$1028,$H11,B$3:B$1028) -> -0.001159725 | J11: =AVERAGEIF($A$3:$A$1028,$H11,C$3:C$1028) -> -0.00044462558 | K11: =AVERAGEIF($A$3:$A$1028,$H11,D$3:D$1028) -> -0.00036148371 | L11: =AVERAGEIF($A$3:$A$1028,$H11,E$3:E$1028) -> -0.00028248958 | M11: =AVERAGEIF($A$3:$A$1028,$H11,F$3:F$1028) -> -0.00029089428 | N11: CAC40 | O11: 0.69579364 | P11: 0.53845445 | Q11: 0.71870142 | R11: 0.74214171 | S11: 1
A12: 2020 | B12: ='CALCULATION of avg returns'!AO12 -> 0.013319365 | C12: ='CALCULATION of avg returns'!AP12 -> 0.0087905503 | D12: ='CALCULATION of avg returns'!AQ12 -> 0.0059603868 | E12: ='CALCULATION of avg returns'!AR12 -> 0.004081969 | F12: ='CALCULATION of avg returns'!AS12 -> 0.0016219507 | H12: 2023 | I12: =AVERAGEIF($A$3:$A$1028,$H12,B$3:B$1028) -> 6.9683905e-05 | J12: =AVERAGEIF($A$3:$A$1028,$H12,C$3:C$1028) -> 0.00080645849 | K12: =AVERAGEIF($A$3:$A$1028,$H12,D$3:D$1028) -> 0.00068572294 | L12: =AVERAGEIF($A$3:$A$1028,$H12,E$3:E$1028) -> 0.00062251281 | M12: =AVERAGEIF($A$3:$A$1028,$H12,F$3:F$1028) -> 0.00060548674
A13: 2020 | B13: ='CALCULATION of avg returns'!AO13 -> 0.010215133 | C13: ='CALCULATION of avg returns'!AP13 -> 0.01447691 | D13: ='CALCULATION of avg returns'!AQ13 -> 0.014464495 | E13: ='CALCULATION of avg returns'!AR13 -> 0.014491949 | F13: ='CALCULATION of avg returns'!AS13 -> 0.0075169863 | H13: 4 | I13: =AVERAGE(B3:B1028) -> 0.00012616186 | J13: =AVERAGE(C3:C1028) -> 0.0007218548 | K13: =AVERAGE(D3:D1028) -> 0.00063376492 | L13: =AVERAGE(E3:E1028) -> 0.00051210266 | M13: =AVERAGE(F3:F1028) -> 0.00031518937 | Q13: PTF 10% | R13: PTF 20% | S13: PTF 50% | T13: PTF 100%
A14: 2020 | B14: ='CALCULATION of avg returns'!AO14 -> -0.013206306 | C14: ='CALCULATION of avg returns'!AP14 -> -0.011828607 | D14: ='CALCULATION of avg returns'!AQ14 -> -0.012465678 | E14: ='CALCULATION of avg returns'!AR14 -> -0.0094590382 | F14: ='CALCULATION of avg returns'!AS14 -> 0.00080444555 | O14: SUM OF RETURN | P14: 2020 | Q14: =SUMIF($A$3:$A$1028,$P14,B$3:B$1028) -> 0.10633349 | R14: =SUMIF($A$3:$A$1028,$P14,C$3:C$1028) -> 0.19872474 | S14: =SUMIF($A$3:$A$1028,$P14,D$3:D$1028) -> 0.15894515 | T14: =SUMIF($A$3:$A$1028,$P14,E$3:E$1028) -> 0.093356015
A15: 2020 | B15: ='CALCULATION of avg returns'!AO15 -> -0.015099138 | C15: ='CALCULATION of avg returns'!AP15 -> -0.012606843 | D15: ='CALCULATION of avg returns'!AQ15 -> -0.010136558 | E15: ='CALCULATION of avg returns'!AR15 -> -0.010591989 | F15: ='CALCULATION of avg returns'!AS15 -> -0.012682893 | P15: 2021 | Q15: =SUMIF($A$3:$A$1028,$P15,B$3:B$1028) -> 0.30345819 | R15: =SUMIF($A$3:$A$1028,$P15,C$3:C$1028) -> 0.4513266 | S15: =SUMIF($A$3:$A$1028,$P15,D$3:D$1028) -> 0.41002534 | T15: =SUMIF($A$3:$A$1028,$P15,E$3:E$1028) -> 0.34654289
A16: 2020 | B16: ='CALCULATION of avg returns'!AO16 -> 0.006430586 | C16: ='CALCULATION of avg returns'!AP16 -> 0.0045325707 | D16: ='CALCULATION of avg returns'!AQ16 -> 0.00071425705 | E16: ='CALCULATION of avg returns'!AR16 -> -0.0019885929 | F16: ='CALCULATION of avg returns'!AS16 -> 0.0019352137 | P16: 2022 | Q16: =SUMIF($A$3:$A$1028,$P16,B$3:B$1028) -> -0.29804932 | R16: =SUMIF($A$3:$A$1028,$P16,C$3:C$1028) -> -0.11426878 | S16: =SUMIF($A$3:$A$1028,$P16,D$3:D$1028) -> -0.092901314 | T16: =SUMIF($A$3:$A$1028,$P16,E$3:E$1028) -> -0.072599823
A17: 2020 | B17: ='CALCULATION of avg returns'!AO17 -> -0.023054504 | C17: ='CALCULATION of avg returns'!AP17 -> -0.016561384 | D17: ='CALCULATION of avg returns'!AQ17 -> -0.015822734 | E17: ='CALCULATION of avg returns'!AR17 -> -0.01352456 | F17: ='CALCULATION of avg returns'!AS17 -> -0.0073096372 | P17: 2023 | Q17: =SUMIF($A$3:$A$1028,$P17,B$3:B$1028) -> 0.017699712 | R17: =SUMIF($A$3:$A$1028,$P17,C$3:C$1028) -> 0.20484046 | S17: =SUMIF($A$3:$A$1028,$P17,D$3:D$1028) -> 0.17417363 | T17: =SUMIF($A$3:$A$1028,$P17,E$3:E$1028) -> 0.15811825
A18: 2020 | B18: ='CALCULATION of avg returns'!AO18 -> 0.0028047988 | C18: ='CALCULATION of avg returns'!AP18 -> 0.0061777858 | D18: ='CALCULATION of avg returns'!AQ18 -> 0.0072359254 | E18: ='CALCULATION of avg returns'!AR18 -> 0.0078106696 | F18: ='CALCULATION of avg returns'!AS18 -> 0.0092085201
A19: 2020 | B19: ='CALCULATION of avg returns'!AO19 -> -0.031020761 | C19: ='CALCULATION of avg returns'!AP19 -> -0.036158352 | D19: ='CALCULATION of avg returns'!AQ19 -> -0.03292236 | E19: ='CALCULATION of avg returns'!AR19 -> -0.032715998 | F19: ='CALCULATION of avg returns'!AS19 -> -0.027551327 | G19: AVERAGE daily RISK | I19: PTF 10% | J19: PTF 20% | K19: PTF 50% | L19: PTF 100% | M19: CAC40
A20: 2020 | B20: ='CALCULATION of avg returns'!AO20 -> 0.011401656 | C20: ='CALCULATION of avg returns'!AP20 -> 0.01015499 | D20: ='CALCULATION of avg returns'!AQ20 -> 0.013108638 | E20: ='CALCULATION of avg returns'!AR20 -> 0.012477579 | F20: ='CALCULATION of avg returns'!AS20 -> 0.0010647753 | H20: 2020 | I20: =_xlfn.STDEV.S(B3:B259) -> 0.023547358 | J20: =_xlfn.STDEV.S(C3:C259) -> 0.019673415 | K20: =_xlfn.STDEV.S(D3:D259) -> 0.019125869 | L20: =_xlfn.STDEV.S(E3:E259) -> 0.019728774 | M20: =_xlfn.STDEV.S(F3:F259) -> 0.020196029
A21: 2020 | B21: ='CALCULATION of avg returns'!AO21 -> 0.0080299925 | C21: ='CALCULATION of avg returns'!AP21 -> 0.0068536524 | D21: ='CALCULATION of avg returns'!AQ21 -> 0.0039675823 | E21: ='CALCULATION of avg returns'!AR21 -> 0.0043003391 | F21: ='CALCULATION of avg returns'!AS21 -> 0.010073021 | H21: 2021 | I21: =_xlfn.STDEV.S(B260:B517) -> 0.014092721 | J21: =_xlfn.STDEV.S(C260:C517) -> 0.013069733 | K21: =_xlfn.STDEV.S(D260:D517) -> 0.012013791 | L21: =_xlfn.STDEV.S(E260:E517) -> 0.011267582 | M21: =_xlfn.STDEV.S(F260:F517) -> 0.0092290634
A22: 2020 | B22: ='CALCULATION of avg returns'!AO22 -> -0.013306737 | C22: ='CALCULATION of avg returns'!AP22 -> -0.015756337 | D22: ='CALCULATION of avg returns'!AQ22 -> -0.01512086 | E22: ='CALCULATION of avg returns'!AR22 -> -0.014726738 | F22: ='CALCULATION of avg returns'!AS22 -> -0.011794673 | H22: 2022 | I22: =_xlfn.STDEV.S(B518:B774) -> 0.019574992 | J22: =_xlfn.STDEV.S(C518:C774) -> 0.020223077 | K22: =_xlfn.STDEV.S(D518:D774) -> 0.018827885 | L22: =_xlfn.STDEV.S(E518:E774) -> 0.017226774 | M22: =_xlfn.STDEV.S(F518:F774) -> 0.01370195
A23: 2020 | B23: ='CALCULATION of avg returns'!AO23 -> -0.011529783 | C23: ='CALCULATION of avg returns'!AP23 -> -0.0068294371 | D23: ='CALCULATION of avg returns'!AQ23 -> -0.0079917494 | E23: ='CALCULATION of avg returns'!AR23 -> -0.0097196233 | F23: ='CALCULATION of avg returns'!AS23 -> -0.0081091945 | H23: 2023 | I23: =_xlfn.STDEV.S(B775:B1028) -> 0.013976509 | J23: =_xlfn.STDEV.S(C775:C1028) -> 0.013868085 | K23: =_xlfn.STDEV.S(D775:D1028) -> 0.012963744 | L23: =_xlfn.STDEV.S(E775:E1028) -> 0.011719348 | M23: =_xlfn.STDEV.S(F775:F1028) -> 0.0085918956
A24: 2020 | B24: ='CALCULATION of avg returns'!AO24 -> 0.0026785596 | C24: ='CALCULATION of avg returns'!AP24 -> 0.0030896881 | D24: ='CALCULATION of avg returns'!AQ24 -> 0.0042511459 | E24: ='CALCULATION of avg returns'!AR24 -> 0.0048705356 | F24: ='CALCULATION of avg returns'!AS24 -> 0.00087945591 | H24: 4 | I24: =_xlfn.STDEV.S(B3:B1028) -> 0.018245886 | J24: =_xlfn.STDEV.S(C3:C1028) -> 0.017021158 | K24: =_xlfn.STDEV.S(D3:D1028) -> 0.016063792 | L24: =_xlfn.STDEV.S(E3:E1028) -> 0.015407881 | M24: =_xlfn.STDEV.S(F3:F1028) -> 0.013734019
A25: 2020 | B25: ='CALCULATION of avg returns'!AO25 -> 0.025253323 | C25: ='CALCULATION of avg returns'!AP25 -> 0.021761644 | D25: ='CALCULATION of avg returns'!AQ25 -> 0.021278914 | E25: ='CALCULATION of avg returns'!AR25 -> 0.020258131 | F25: ='CALCULATION of avg returns'!AS25 -> 0.010110025
A26: 2020 | B26: ='CALCULATION of avg returns'!AO26 -> 0.0080093442 | C26: ='CALCULATION of avg returns'!AP26 -> 0.0098676467 | D26: ='CALCULATION of avg returns'!AQ26 -> 0.0097426848 | E26: ='CALCULATION of avg returns'!AR26 -> 0.0078995739 | F26: ='CALCULATION of avg returns'!AS26 -> 0.0084720322 | I26: PTF 10% | J26: PTF 20% | K26: PTF 50% | L26: PTF 100%
A27: 2020 | B27: ='CALCULATION of avg returns'!AO27 -> 0.00076401003 | C27: ='CALCULATION of avg returns'!AP27 -> -0.004467957 | D27: ='CALCULATION of avg returns'!AQ27 -> -0.001320902 | E27: ='CALCULATION of avg returns'!AR27 -> 0.0022284026 | F27: ='CALCULATION of avg returns'!AS27 -> 0.016246962 | G27: ANNUALISED RISK | H27: 2020 | I27: =I20*SQRT($I4) -> 0.37749286 | J27: =J20*SQRT($I4) -> 0.31538884 | K27: =K20*SQRT($I4) -> 0.306611 | L27: =L20*SQRT($I4) -> 0.31627631
A28: 2020 | B28: ='CALCULATION of avg returns'!AO28 -> -0.010700699 | C28: ='CALCULATION of avg returns'!AP28 -> -0.0044424787 | D28: ='CALCULATION of avg returns'!AQ28 -> -0.0041836407 | E28: ='CALCULATION of avg returns'!AR28 -> -0.0019476714 | F28: ='CALCULATION of avg returns'!AS28 -> -0.0014312937 | H28: 2021 | I28: =I21*SQRT($I5) -> 0.22636262 | J28: =J21*SQRT($I5) -> 0.20993099 | K28: =K21*SQRT($I5) -> 0.19297006 | L28: =L21*SQRT($I5) -> 0.18098417
A29: 2020 | B29: ='CALCULATION of avg returns'!AO29 -> -0.0047844428 | C29: ='CALCULATION of avg returns'!AP29 -> -0.0019600157 | D29: ='CALCULATION of avg returns'!AQ29 -> -0.0013649869 | E29: ='CALCULATION of avg returns'!AR29 -> -0.0017738414 | F29: ='CALCULATION of avg returns'!AS29 -> -0.0010066751 | H29: 2022 | I29: =I22*SQRT($I6) -> 0.31381099 | J29: =J22*SQRT($I6) -> 0.32420058 | K29: =K22*SQRT($I6) -> 0.30183396 | L29: =L22*SQRT($I6) -> 0.27616619
A30: 2020 | B30: ='CALCULATION of avg returns'!AO30 -> 0.00078831739 | C30: ='CALCULATION of avg returns'!AP30 -> 0.00016365541 | D30: ='CALCULATION of avg returns'!AQ30 -> 0.0018661221 | E30: ='CALCULATION of avg returns'!AR30 -> 0.0022663464 | F30: ='CALCULATION of avg returns'!AS30 -> 0.0064865839 | H30: 2023 | I30: =I23*SQRT($I7) -> 0.22274889 | J30: =J23*SQRT($I7) -> 0.2210209 | K30: =K23*SQRT($I7) -> 0.20660807 | L30: =L23*SQRT($I7) -> 0.18677568
A31: 2020 | B31: ='CALCULATION of avg returns'!AO31 -> 0.04850144 | C31: ='CALCULATION of avg returns'!AP31 -> 0.0340413 | D31: ='CALCULATION of avg returns'!AQ31 -> 0.027453607 | E31: ='CALCULATION of avg returns'!AR31 -> 0.018536099 | F31: ='CALCULATION of avg returns'!AS31 -> 0.0050026605 | I31: PTF 10% | J31: PTF 20% | K31: PTF 50% | L31: PTF 100%
A32: 2020 | B32: ='CALCULATION of avg returns'!AO32 -> -0.0058992327 | C32: ='CALCULATION of avg returns'!AP32 -> -0.0022280455 | D32: ='CALCULATION of avg returns'!AQ32 -> -0.001280145 | E32: ='CALCULATION of avg returns'!AR32 -> -0.0016898681 | F32: ='CALCULATION of avg returns'!AS32 -> -0.0057216183 | G32: BETA | H32: 2020 | I32: =_xlfn.COVARIANCE.S(B3:B259,$F$3:$F$259)/_xlfn.VAR.S($F$3:$F$259) -> 0.88657356 | J32: =_xlfn.COVARIANCE.S(C3:C259,$F$3:$F$259)/_xlfn.VAR.S($F$3:$F$259) -> 0.71526424 | K32: =_xlfn.COVARIANCE.S(D3:D259,$F$3:$F$259)/_xlfn.VAR.S($F$3:$F$259) -> 0.73059643 | L32: =_xlfn.COVARIANCE.S(E3:E259,$F$3:$F$259)/_xlfn.VAR.S($F$3:$F$259) -> 0.77916166
A33: 2020 | B33: ='CALCULATION of avg returns'!AO33 -> -0.019611487 | C33: ='CALCULATION of avg returns'!AP33 -> -0.013785097 | D33: ='CALCULATION of avg returns'!AQ33 -> -0.011548015 | E33: ='CALCULATION of avg returns'!AR33 -> -0.01002784 | F33: ='CALCULATION of avg returns'!AS33 -> 0.0064462832 | H33: 2021 | I33: =_xlfn.COVARIANCE.S(B260:B517,$F$260:$F$517)/_xlfn.VAR.S($F$260:$F$517) -> 0.99119506 | J33: =_xlfn.COVARIANCE.S(C260:C517,$F$260:$F$517)/_xlfn.VAR.S($F$260:$F$517) -> 0.8544547 | K33: =_xlfn.COVARIANCE.S(D260:D517,$F$260:$F$517)/_xlfn.VAR.S($F$260:$F$517) -> 0.85597723 | L33: =_xlfn.COVARIANCE.S(E260:E517,$F$260:$F$517)/_xlfn.VAR.S($F$260:$F$517) -> 0.84584431
A34: 2020 | B34: ='CALCULATION of avg returns'!AO34 -> 0.0025020535 | C34: ='CALCULATION of avg returns'!AP34 -> 0.0046506841 | D34: ='CALCULATION of avg returns'!AQ34 -> 0.0041641329 | E34: ='CALCULATION of avg returns'!AR34 -> 0.0031061911 | F34: ='CALCULATION of avg returns'!AS34 -> -0.00036590552 | H34: 2022 | I34: =_xlfn.COVARIANCE.S(B518:B774,$F$518:$F$774)/_xlfn.VAR.S($F$518:$F$774) -> 0.95083379 | J34: =_xlfn.COVARIANCE.S(C518:C774,$F$518:$F$774)/_xlfn.VAR.S($F$518:$F$774) -> 0.90603183 | K34: =_xlfn.COVARIANCE.S(D518:D774,$F$518:$F$774)/_xlfn.VAR.S($F$518:$F$774) -> 0.88756968 | L34: =_xlfn.COVARIANCE.S(E518:E774,$F$518:$F$774)/_xlfn.VAR.S($F$518:$F$774) -> 0.84060331
A35: 2020 | B35: ='CALCULATION of avg returns'!AO35 -> -0.01598326 | C35: ='CALCULATION of avg returns'!AP35 -> -0.014239615 | D35: ='CALCULATION of avg returns'!AQ35 -> -0.012151838 | E35: ='CALCULATION of avg returns'!AR35 -> -0.0095510214 | F35: ='CALCULATION of avg returns'!AS35 -> -0.0041187683 | H35: 2023 | I35: =_xlfn.COVARIANCE.S(B775:B1028,$F$775:$F$1028)/_xlfn.VAR.S($F$775:$F$1028) -> 0.98441281 | J35: =_xlfn.COVARIANCE.S(C775:C1028,$F$775:$F$1028)/_xlfn.VAR.S($F$775:$F$1028) -> 0.94530633 | K35: =_xlfn.COVARIANCE.S(D775:D1028,$F$775:$F$1028)/_xlfn.VAR.S($F$775:$F$1028) -> 0.9278718 | L35: =_xlfn.COVARIANCE.S(E775:E1028,$F$775:$F$1028)/_xlfn.VAR.S($F$775:$F$1028) -> 0.86713662
A36: 2020 | B36: ='CALCULATION of avg returns'!AO36 -> 0.024402741 | C36: ='CALCULATION of avg returns'!AP36 -> 0.020713172 | D36: ='CALCULATION of avg returns'!AQ36 -> 0.018456042 | E36: ='CALCULATION of avg returns'!AR36 -> 0.017099222 | F36: ='CALCULATION of avg returns'!AS36 -> 0.0054172724 | H36: 4 years | I36: =_xlfn.COVARIANCE.S(B3:B1028,$F$3:$F$1028)/_xlfn.VAR.S($F$3:$F$1028) -> 0.92437413 | J36: =_xlfn.COVARIANCE.S(C3:C1028,$F$3:$F$1028)/_xlfn.VAR.S($F$3:$F$1028) -> 0.80152073 | K36: =_xlfn.COVARIANCE.S(D3:D1028,$F$3:$F$1028)/_xlfn.VAR.S($F$3:$F$1028) -> 0.8035161 | L36: =_xlfn.COVARIANCE.S(E3:E1028,$F$3:$F$1028)/_xlfn.VAR.S($F$3:$F$1028) -> 0.81086794
A37: 2020 | B37: ='CALCULATION of avg returns'!AO37 -> -0.021195448 | C37: ='CALCULATION of avg returns'!AP37 -> -0.019217431 | D37: ='CALCULATION of avg returns'!AQ37 -> -0.017535607 | E37: ='CALCULATION of avg returns'!AR37 -> -0.016312371 | F37: ='CALCULATION of avg returns'!AS37 -> -0.0017060069
A38: 2020 | B38: ='CALCULATION of avg returns'!AO38 -> -0.0078569147 | C38: ='CALCULATION of avg returns'!AP38 -> -0.0076364604 | D38: ='CALCULATION of avg returns'!AQ38 -> -0.0068124092 | E38: ='CALCULATION of avg returns'!AR38 -> -0.0063581251 | F38: ='CALCULATION of avg returns'!AS38 -> -0.011078304
A39: 2020 | B39: ='CALCULATION of avg returns'!AO39 -> -0.041810456 | C39: ='CALCULATION of avg returns'!AP39 -> -0.038423819 | D39: ='CALCULATION of avg returns'!AQ39 -> -0.040754464 | E39: ='CALCULATION of avg returns'!AR39 -> -0.041279762 | F39: ='CALCULATION of avg returns'!AS39 -> -0.038359404 | G39: 4 years | H39: PTF 10% | I39: PTF 20% | J39: PTF 50% | K39: PTF 100%
A40: 2020 | B40: ='CALCULATION of avg returns'!AO40 -> -0.020292153 | C40: ='CALCULATION of avg returns'!AP40 -> -0.0154547 | D40: ='CALCULATION of avg returns'!AQ40 -> -0.016255904 | E40: ='CALCULATION of avg returns'!AR40 -> -0.017102309 | F40: ='CALCULATION of avg returns'!AS40 -> -0.016384599 | G40: GLOBAL RETURN | H40: =('CALCULATION of avg returns'!AI1029-'CALCULATION of avg returns'!AI3)/'CALCULATION of avg returns'!AI3 -> -0.04061787 | I40: =('CALCULATION of avg returns'!AJ1029-'CALCULATION of avg returns'!AJ3)/'CALCULATION of avg returns'!AJ3 -> 0.80758721 | J40: =('CALCULATION of avg returns'!AK1029-'CALCULATION of avg returns'!AK3)/'CALCULATION of avg returns'!AK3 -> 0.67829166 | K40: =('CALCULATION of avg returns'!AL1029-'CALCULATION of avg returns'!AL3)/'CALCULATION of avg returns'!AL3 -> 0.49700992
...

Sheet CALCULATION of avg returns
AG1: AVERAGE CAP PER TRESHHOLD | AN1: RETURN OF THE AVG CAP PER TRESHHOLD | AU1: RETURN OF THE AVG CAP PER TRESHHOLD
A2: série | B2: CAC40 | C2: MC | D2: OR | E2: RMS | F2: AIR | G2: SU | H2: EL | I2: SAF | J2: TTE | K2: AI | L2: SAN | M2: BNP | N2: CDI | O2: CS | P2: DG | Q2: BN | R2: ACA | S2: HO | T2: SGO | U2: ENGI | V2: GLE | W2: GLE2 | X2: ORA | Y2: DSY | Z2: LR | AA2: KER | AB2: RI | AC2: STLAP | AD2: ML | AE2: CAP | AG2: year | AI2: AVG PTF 10% | AJ2: AVG PTF 20% | AK2: AVG PTF 50% | AL2: AVG PTF 100% | AN2: year | AO2: AVG PTF 10% | AP2: AVG PTF 20% | AQ2: AVG PTF 50% | AR2: AVG PTF 100% | AS2: CAC40 | AU2: year | AV2: AVG PTF 10% | AW2: AVG PTF 20% | AX2: AVG PTF 50% | AY2: AVG PTF 100% | AZ2: CAC40
A3: 1 | B3: 6011.21 | C3: 419.15 | D3: 264.2 | E3: 671 | F3: 133.52 | G3: 93.06 | H3: 136.7 | I3: 137.6 | J3: 49.82 | K3: 104.71 | L3: 89.73 | M3: 53.58 | N3: 461.8 | O3: 25.46 | P3: 99.84 | Q3: 73.98 | R3: 13.19 | S3: 92.94 | T3: 36.99 | U3: 14.7 | V3: 31.66 | W3: 31.66 | X3: 13.18 | Y3: 29.46 | Z3: 73.54 | AA3: 598 | AB3: 160.35 | AD3: 27.11 | AE3: 111.05 | AG3: 2020 | AI3: =AVERAGE(G3,AA3,AE3) -> 267.37 | AJ3: =AVERAGE(E3,Y3,AD3,G3,AA3,AE3) -> 254.94667 | AK3: =AVERAGE(Z3,V3,Q3,O3,M3,K3,H3,C3,E3,Y3,AD3,G3,AA3,AE3) -> 174.89 | AL3: =AVERAGE(AC3,AB3,X3,W3,U3,T3,S3,R3,P3,N3,L3,J3,I3,F3,D3,Z3,V3,Q3,O3,M3,K3,H3,C3,E3,Y3,AD3,G3,AA3,AE3) -> 144.57071 | AN3: 2020 | AO3: =(AI4-AI3)/AI3 -> 0.0034409246 | AP3: =(AJ4-AJ3)/AJ3 -> 0.0047264787 | AQ3: =(AK4-AK3)/AK3 -> 0.0024300989 | AR3: =(AL4-AL3)/AL3 -> 0.0022529756 | AS3: =(B4-B3)/B3 -> -0.0027648344 | AU3: 2020
A4: 2 | B4: 5994.59 | C4: 419.1 | D4: 263.9 | E4: 675.4 | F4: 134.04 | G4: 92.82 | H4: 136.25 | I4: 138 | J4: 50.38 | K4: 104.38 | L4: 90.29 | M4: 52.94 | N4: 462.8 | O4: 25.47 | P4: 99.22 | Q4: 74.62 | R4: 13.11 | S4: 94.12 | T4: 36.34 | U4: 14.69 | V4: 31.34 | W4: 31.34 | X4: 13.26 | Y4: 29.69 | Z4: 73.4 | AA4: 600.9 | AB4: 161.2 | AD4: 26.95 | AE4: 111.15 | AG4: 2020 | AI4: =AVERAGE(G4,AA4,AE4) -> 268.29 | AJ4: =AVERAGE(E4,Y4,AD4,G4,AA4,AE4) -> 256.15167 | AK4: =AVERAGE(Z4,V4,Q4,O4,M4,K4,H4,C4,E4,Y4,AD4,G4,AA4,AE4) -> 175.315 | AL4: =AVERAGE(AC4,AB4,X4,W4,U4,T4,S4,R4,P4,N4,L4,J4,I4,F4,D4,Z4,V4,Q4,O4,M4,K4,H4,C4,E4,Y4,AD4,G4,AA4,AE4) -> 144.89643 | AN4: 2020 | AO4: =(AI5-AI4)/AI4 -> -0.014996211 | AP4: =(AJ5-AJ4)/AJ4 -> -0.011627226 | AQ4: =(AK5-AK4)/AK4 -> -0.0095501567 | AR4: =(AL5-AL4)/AL4 -> -0.0068546499 | AS4: =(B5-B4)/B4 -> -0.0065625839 | AU4: 2020 | AV4: =(AI4-AI3)/AI3 -> 0.0034409246 | AW4: =(AJ4-AJ3)/AJ3 -> 0.0047264787 | AX4: =(AK4-AK3)/AK3 -> 0.0024300989 | AY4: =(AL4-AL3)/AL3 -> 0.0022529756 | AZ4: =(B4-B3)/B3 -> -0.0027648344
A5: 3 | B5: 5955.25 | C5: 415.15 | D5: 263 | E5: 669.8 | F5: 133.46 | G5: 92.7 | H5: 136.1 | I5: 136.45 | J5: 50.44 | K5: 103.68 | L5: 90.85 | M5: 52.68 | N5: 461.2 | O5: 25.14 | P5: 98.72 | Q5: 74.76 | R5: 12.98 | S5: 95.04 | T5: 36 | U5: 14.71 | V5: 31.08 | W5: 31.08 | X5: 13.19 | Y5: 29.5 | Z5: 73.34 | AA5: 590.8 | AB5: 161.2 | AD5: 26.94 | AE5: 109.3 | AG5: 2020 | AI5: =AVERAGE(G5,AA5,AE5) -> 264.26667 | AJ5: =AVERAGE(E5,Y5,AD5,G5,AA5,AE5) -> 253.17333 | AK5: =AVERAGE(Z5,V5,Q5,O5,M5,K5,H5,C5,E5,Y5,AD5,G5,AA5,AE5) -> 173.64071 | AL5: =AVERAGE(AC5,AB5,X5,W5,U5,T5,S5,R5,P5,N5,L5,J5,I5,F5,D5,Z5,V5,Q5,O5,M5,K5,H5,C5,E5,Y5,AD5,G5,AA5,AE5) -> 143.90321 | AN5: 2020 | AO5: =(AI6-AI5)/AI5 -> 0.0065211907 | AP5: =(AJ6-AJ5)/AJ5 -> 0.0091373499 | AQ5: =(AK6-AK5)/AK5 -> 0.006026401 | AR5: =(AL6-AL5)/AL5 -> 0.0022882443 | AS5: =(B6-B5)/B5 -> 0.0075143781 | AU5: 2020 | AV5: =(AI5-AI4)/AI4 -> -0.014996211 | AW5: =(AJ5-AJ4)/AJ4 -> -0.011627226 | AX5: =(AK5-AK4)/AK4 -> -0.0095501567 | AY5: =(AL5-AL4)/AL4 -> -0.0068546499 | AZ5: =(B5-B4)/B4 -> -0.0065625839
A6: 4 | B6: 6000 | C6: 416 | D6: 259.6 | E6: 678.2 | F6: 132 | G6: 92.32 | H6: 137.05 | I6: 137.7 | J6: 50.11 | K6: 103.22 | L6: 90.54 | M6: 52.66 | N6: 461.2 | O6: 25.29 | P6: 98.04 | Q6: 74.06 | R6: 12.95 | S6: 94.8 | T6: 35.85 | U6: 14.89 | V6: 31.46 | W6: 31.46 | X6: 13.2 | Y6: 29.74 | Z6: 72.96 | AA6: 596.3 | AB6: 160.55 | AD6: 27.01 | AE6: 109.35 | AG6: 2020 | AI6: =AVERAGE(G6,AA6,AE6) -> 265.99 | AJ6: =AVERAGE(E6,Y6,AD6,G6,AA6,AE6) -> 255.48667 | AK6: =AVERAGE(Z6,V6,Q6,O6,M6,K6,H6,C6,E6,Y6,AD6,G6,AA6,AE6) -> 174.68714 | AL6: =AVERAGE(AC6,AB6,X6,W6,U6,T6,S6,R6,P6,N6,L6,J6,I6,F6,D6,Z6,V6,Q6,O6,M6,K6,H6,C6,E6,Y6,AD6,G6,AA6,AE6) -> 144.2325 | AN6: 2020 | AO6: =(AI7-AI6)/AI6 -> 0.0011779891 | AP6: =(AJ7-AJ6)/AJ6 -> 0.0051209456 | AQ6: =(AK7-AK6)/AK6 -> 0.0046573057 | AR6: =(AL7-AL6)/AL6 -> 0.0049696546 | AS6: =(B7-B6)/B6 -> -0.0045383333 | AU6: 2020 | AV6: =(AI6-AI5)/AI5 -> 0.0065211907 | AW6: =(AJ6-AJ5)/AJ5 -> 0.0091373499 | AX6: =(AK6-AK5)/AK5 -> 0.006026401 | AY6: =(AL6-AL5)/AL5 -> 0.0022882443 | AZ6: =(B6-B5)/B5 -> 0.0075143781
A7: 5 | B7: 5972.77 | C7: 418.8 | D7: 261.2 | E7: 684.2 | F7: 134.38 | G7: 92.56 | H7: 138.9 | I7: 137.5 | J7: 50.24 | K7: 103.31 | L7: 90.84 | M7: 52.78 | N7: 463.2 | O7: 25.28 | P7: 99.92 | Q7: 72.56 | R7: 13.01 | S7: 96.18 | T7: 35.9 | U7: 14.87 | V7: 31.77 | W7: 31.77 | X7: 13.11 | Y7: 30.1 | Z7: 72.84 | AA7: 597.3 | AB7: 159.45 | AD7: 27.56 | AE7: 109.05 | AG7: 2020 | AI7: =AVERAGE(G7,AA7,AE7) -> 266.30333 | AJ7: =AVERAGE(E7,Y7,AD7,G7,AA7,AE7) -> 256.795 | AK7: =AVERAGE(Z7,V7,Q7,O7,M7,K7,H7,C7,E7,Y7,AD7,G7,AA7,AE7) -> 175.50071 | AL7: =AVERAGE(AC7,AB7,X7,W7,U7,T7,S7,R7,P7,N7,L7,J7,I7,F7,D7,Z7,V7,Q7,O7,M7,K7,H7,C7,E7,Y7,AD7,G7,AA7,AE7) -> 144.94929 | AN7: 2020 | AO7: =(AI8-AI7)/AI7 -> -0.0027036838 | AP7: =(AJ8-AJ7)/AJ7 -> 0.00075287032 | AQ7: =(AK8-AK7)/AK7 -> 0.0037647384 | AR7: =(AL8-AL7)/AL7 -> 0.0036687709 | AS7: =(B8-B7)/B7 -> 0.010276639 | AU7: 2020 | AV7: =(AI7-AI6)/AI6 -> 0.0011779891 | AW7: =(AJ7-AJ6)/AJ6 -> 0.0051209456 | AX7: =(AK7-AK6)/AK6 -> 0.0046573057 | AY7: =(AL7-AL6)/AL6 -> 0.0049696546 | AZ7: =(B7-B6)/B6 -> -0.0045383333
A8: 6 | B8: 6034.15 | C8: 424.5 | D8: 262.8 | E8: 687 | F8: 134.92 | G8: 91.8 | H8: 141.15 | I8: 139.45 | J8: 49.96 | K8: 103.72 | L8: 91.5 | M8: 52.4 | N8: 465 | O8: 25.25 | P8: 98.92 | Q8: 72.7 | R8: 13.02 | S8: 96.5 | T8: 35.69 | U8: 14.81 | V8: 31.79 | W8: 31.79 | X8: 13.15 | Y8: 30.49 | Z8: 72.82 | AA8: 595.9 | AB8: 159.7 | AD8: 27.69 | AE8: 109.05 | AG8: 2020 | AI8: =AVERAGE(G8,AA8,AE8) -> 265.58333 | AJ8: =AVERAGE(E8,Y8,AD8,G8,AA8,AE8) -> 256.98833 | AK8: =AVERAGE(Z8,V8,Q8,O8,M8,K8,H8,C8,E8,Y8,AD8,G8,AA8,AE8) -> 176.16143 | AL8: =AVERAGE(AC8,AB8,X8,W8,U8,T8,S8,R8,P8,N8,L8,J8,I8,F8,D8,Z8,V8,Q8,O8,M8,K8,H8,C8,E8,Y8,AD8,G8,AA8,AE8) -> 145.48107 | AN8: 2020 | AO8: =(AI9-AI8)/AI8 -> -0.0028365234 | AP8: =(AJ9-AJ8)/AJ8 -> 6.4853787e-05 | AQ8: =(AK9-AK8)/AK8 -> -0.00066091977 | AR8: =(AL9-AL8)/AL8 -> -0.0006751001 | AS8: =(B9-B8)/B8 -> -0.00097113927 | AU8: 2020 | AV8: =(AI8-AI7)/AI7 -> -0.0027036838 | AW8: =(AJ8-AJ7)/AJ7 -> 0.00075287032 | AX8: =(AK8-AK7)/AK7 -> 0.0037647384 | AY8: =(AL8-AL7)/AL7 -> 0.0036687709 | AZ8: =(B8-B7)/B7 -> 0.010276639
A9: 7 | B9: 6028.29 | C9: 423.65 | D9: 263.9 | E9: 689 | F9: 134.42 | G9: 92.14 | H9: 141 | I9: 138.5 | J9: 49.79 | K9: 103.97 | L9: 92.22 | M9: 52.16 | N9: 465.6 | O9: 25.36 | P9: 99.42 | Q9: 72.6 | R9: 12.88 | S9: 95.92 | T9: 35.22 | U9: 14.76 | V9: 31.44 | W9: 31.44 | X9: 13.12 | Y9: 30.8 | Z9: 72.42 | AA9: 592.1 | AB9: 158.9 | AD9: 27.74 | AE9: 110.25 | AG9: 2020 | AI9: =AVERAGE(G9,AA9,AE9) -> 264.83 | AJ9: =AVERAGE(E9,Y9,AD9,G9,AA9,AE9) -> 257.005 | AK9: =AVERAGE(Z9,V9,Q9,O9,M9,K9,H9,C9,E9,Y9,AD9,G9,AA9,AE9) -> 176.045 | AL9: =AVERAGE(AC9,AB9,X9,W9,U9,T9,S9,R9,P9,N9,L9,J9,I9,F9,D9,Z9,V9,Q9,O9,M9,K9,H9,C9,E9,Y9,AD9,G9,AA9,AE9) -> 145.38286 | AN9: 2020 | AO9: =(AI10-AI9)/AI9 -> 0.0038641141 | AP9: =(AJ10-AJ9)/AJ9 -> 0.0024188894 | AQ9: =(AK10-AK9)/AK9 -> 0.0016351339 | AR9: =(AL10-AL9)/AL9 -> 0.0021838888 | AS9: =(B10-B9)/B9 -> -0.0016522098 | AU9: 2020 | AV9: =(AI9-AI8)/AI8 -> -0.0028365234 | AW9: =(AJ9-AJ8)/AJ8 -> 6.4853787e-05 | AX9: =(AK9-AK8)/AK8 -> -0.00066091977 | AY9: =(AL9-AL8)/AL8 -> -0.0006751001 | AZ9: =(B9-B8)/B8 -> -0.00097113927
A10: 8 | B10: 6018.33 | C10: 426.75 | D10: 262.5 | E10: 689.6 | F10: 135.12 | G10: 91.86 | H10: 138.8 | I10: 137.45 | J10: 49.56 | K10: 104.34 | L10: 91.57 | M10: 51.93 | N10: 467.6 | O10: 25.34 | P10: 99.74 | Q10: 72.26 | R10: 12.86 | S10: 96.78 | T10: 35.67 | U10: 14.8 | V10: 31.44 | W10: 31.44 | X10: 13.06 | Y10: 30.9 | Z10: 72.04 | AA10: 593.8 | AB10: 162.8 | AD10: 27.7 | AE10: 111.9 | AG10: 2020 | AI10: =AVERAGE(G10,AA10,AE10) -> 265.85333 | AJ10: =AVERAGE(E10,Y10,AD10,G10,AA10,AE10) -> 257.62667 | AK10: =AVERAGE(Z10,V10,Q10,O10,M10,K10,H10,C10,E10,Y10,AD10,G10,AA10,AE10) -> 176.33286 | AL10: =AVERAGE(AC10,AB10,X10,W10,U10,T10,S10,R10,P10,N10,L10,J10,I10,F10,D10,Z10,V10,Q10,O10,M10,K10,H10,C10,E10,Y10,AD10,G10,AA10,AE10) -> 145.70036 | AN10: 2020 | AO10: =(AI11-AI10)/AI10 -> 0.0017678921 | AP10: =(AJ11-AJ10)/AJ10 -> 0.0073361971 | AQ10: =(AK11-AK10)/AK10 -> 0.006793159 | AR10: =(AL11-AL10)/AL10 -> 0.0061206831 | AS10: =(B11-B10)/B10 -> -0.0063605685 | AU10: 2020 | AV10: =(AI10-AI9)/AI9 -> 0.0038641141 | AW10: =(AJ10-AJ9)/AJ9 -> 0.0024188894 | AX10: =(AK10-AK9)/AK9 -> 0.0016351339 | AY10: =(AL10-AL9)/AL9 -> 0.0021838888 | AZ10: =(B10-B9)/B9 -> -0.0016522098
A11: 9 | B11: 5980.05 | C11: 431 | D11: 263.8 | E11: 699.6 | F11: 135.1 | G11: 92.62 | H11: 139.85 | I11: 137.6 | J11: 49.16 | K11: 104.96 | L11: 90.77 | M11: 52.17 | N11: 472 | O11: 24.69 | P11: 100.4 | Q11: 71.4 | R11: 12.92 | S11: 96.46 | T11: 35.95 | U11: 14.81 | V11: 31.44 | W11: 31.44 | X11: 13.04 | Y11: 30.8 | Z11: 72.82 | AA11: 592.1 | AB11: 165.7 | AD11: 27.73 | AE11: 114.25 | AG11: 2020 | AI11: =AVERAGE(G11,AA11,AE11) -> 266.32333 | AJ11: =AVERAGE(E11,Y11,AD11,G11,AA11,AE11) -> 259.51667 | AK11: =AVERAGE(Z11,V11,Q11,O11,M11,K11,H11,C11,E11,Y11,AD11,G11,AA11,AE11) -> 177.53071 | AL11: =AVERAGE(AC11,AB11,X11,W11,U11,T11,S11,R11,P11,N11,L11,J11,I11,F11,D11,Z11,V11,Q11,O11,M11,K11,H11,C11,E11,Y11,AD11,G11,AA11,AE11) -> 146.59214 | AN11: 2020 | AO11: =(AI12-AI11)/AI11 -> 0.0035921249 | AP11: =(AJ12-AJ11)/AJ11 -> 0.0074690129 | AQ11: =(AK12-AK11)/AK11 -> 0.0051218501 | AR11: =(AL12-AL11)/AL11 -> 0.0050870004 | AS11: =(B12-B11)/B11 -> 0.0052223644 | AU11: 2020 | AV11: =(AI11-AI10)/AI10 -> 0.0017678921 | AW11: =(AJ11-AJ10)/AJ10 -> 0.0073361971 | AX11: =(AK11-AK10)/AK10 -> 0.006793159 | AY11: =(AL11-AL10)/AL10 -> 0.0061206831 | AZ11: =(B11-B10)/B10 -> -0.0063605685
A12: 10 | B12: 6011.28 | C12: 431.45 | D12: 269.4 | E12: 708.6 | F12: 134.26 | G12: 92.34 | H12: 142.1 | I12: 139.25 | J12: 48.58 | K12: 104.79 | L12: 91.22 | M12: 50.96 | N12: 473.4 | O12: 24.18 | P12: 100.55 | Q12: 72.44 | R12: 12.77 | S12: 96.32 | T12: 35.42 | U12: 14.9 | V12: 30.95 | W12: 30.95 | X12: 13.03 | Y12: 31.21 | Z12: 72.56 | AA12: 594.6 | AB12: 167.25 | AD12: 27.08 | AE12: 114.9 | AG12: 2020 | AI12: =AVERAGE(G12,AA12,AE12) -> 267.28 | AJ12: =AVERAGE(E12,Y12,AD12,G12,AA12,AE12) -> 261.455 | AK12: =AVERAGE(Z12,V12,Q12,O12,M12,K12,H12,C12,E12,Y12,AD12,G12,AA12,AE12) -> 178.44 | AL12: =AVERAGE(AC12,AB12,X12,W12,U12,T12,S12,R12,P12,N12,L12,J12,I12,F12,D12,Z12,V12,Q12,O12,M12,K12,H12,C12,E12,Y12,AD12,G12,AA12,AE12) -> 147.33786 | AN12: 2020 | AO12: =(AI13-AI12)/AI12 -> 0.013319365 | AP12: =(AJ13-AJ12)/AJ12 -> 0.0087905503 | AQ12: =(AK13-AK12)/AK12 -> 0.0059603868 | AR12: =(AL13-AL12)/AL12 -> 0.004081969 | AS12: =(B13-B12)/B12 -> 0.0016219507 | AU12: 2020 | AV12: =(AI12-AI11)/AI11 -> 0.0035921249 | AW12: =(AJ12-AJ11)/AJ11 -> 0.0074690129 | AX12: =(AK12-AK11)/AK11 -> 0.0051218501 | AY12: =(AL12-AL11)/AL11 -> 0.0050870004 | AZ12: =(B12-B11)/B11 -> 0.0052223644
A13: 11 | B13: 6021.03 | C13: 431.9 | D13: 269.8 | E13: 712 | F13: 133.4 | G13: 92.62 | H13: 142.1 | I13: 141 | J13: 48.79 | K13: 105.25 | L13: 91.11 | M13: 50.59 | N13: 473.6 | O13: 24.2 | P13: 100.45 | Q13: 73.5 | R13: 12.78 | S13: 97.3 | T13: 35.07 | U13: 14.98 | V13: 30.61 | W13: 30.61 | X13: 12.86 | Y13: 31.04 | Z13: 72.38 | AA13: 605.1 | AB13: 167.5 | AD13: 26.96 | AE13: 114.8 | AG13: 2020 | AI13: =AVERAGE(G13,AA13,AE13) -> 270.84 | AJ13: =AVERAGE(E13,Y13,AD13,G13,AA13,AE13) -> 263.75333 | AK13: =AVERAGE(Z13,V13,Q13,O13,M13,K13,H13,C13,E13,Y13,AD13,G13,AA13,AE13) -> 179.50357 | AL13: =AVERAGE(AC13,AB13,X13,W13,U13,T13,S13,R13,P13,N13,L13,J13,I13,F13,D13,Z13,V13,Q13,O13,M13,K13,H13,C13,E13,Y13,AD13,G13,AA13,AE13) -> 147.93929 | AN13: 2020 | AO13: =(AI14-AI13)/AI13 -> 0.010215133 | AP13: =(AJ14-AJ13)/AJ13 -> 0.01447691 | AQ13: =(AK14-AK13)/AK13 -> 0.014464495 | AR13: =(AL14-AL13)/AL13 -> 0.014491949 | AS13: =(B14-B13)/B13 -> 0.0075169863 | AU13: 2020 | AV13: =(AI13-AI12)/AI12 -> 0.013319365 | AW13: =(AJ13-AJ12)/AJ12 -> 0.0087905503 | AX13: =(AK13-AK12)/AK12 -> 0.0059603868 | AY13: =(AL13-AL12)/AL12 -> 0.004081969 | AZ13: =(B13-B12)/B12 -> 0.0016219507
A14: 12 | B14: 6066.29 | C14: 439.05 | D14: 275.3 | E14: 725.6 | F14: 136.78 | G14: 94.22 | H14: 144.7 | I14: 142.55 | J14: 48.51 | K14: 106.94 | L14: 91.69 | M14: 50.75 | N14: 479.2 | O14: 24.38 | P14: 102.4 | Q14: 73.7 | R14: 12.87 | S14: 98.78 | T14: 35.37 | U14: 15.2 | V14: 30.65 | W14: 30.65 | X14: 13.03 | Y14: 31.51 | Z14: 73.8 | AA14: 610.2 | AB14: 170.6 | AD14: 27.5 | AE14: 116.4 | AG14: 2020 | AI14: =AVERAGE(G14,AA14,AE14) -> 273.60667 | AJ14: =AVERAGE(E14,Y14,AD14,G14,AA14,AE14) -> 267.57167 | AK14: =AVERAGE(Z14,V14,Q14,O14,M14,K14,H14,C14,E14,Y14,AD14,G14,AA14,AE14) -> 182.1 | AL14: =AVERAGE(AC14,AB14,X14,W14,U14,T14,S14,R14,P14,N14,L14,J14,I14,F14,D14,Z14,V14,Q14,O14,M14,K14,H14,C14,E14,Y14,AD14,G14,AA14,AE14) -> 150.08321 | AN14: 2020 | AO14: =(AI15-AI14)/AI14 -> -0.013206306 | AP14: =(AJ15-AJ14)/AJ14 -> -0.011828607 | AQ14: =(AK15-AK14)/AK14 -> -0.012465678 | AR14: =(AL15-AL14)/AL14 -> -0.0094590382 | AS14: =(B15-B14)/B14 -> 0.00080444555 | AU14: 2020 | AV14: =(AI14-AI13)/AI13 -> 0.010215133 | AW14: =(AJ14-AJ13)/AJ13 -> 0.01447691 | AX14: =(AK14-AK13)/AK13 -> 0.014464495 | AY14: =(AL14-AL13)/AL13 -> 0.014491949 | AZ14: =(B14-B13)/B13 -> 0.0075169863
A15: 13 | B15: 6071.17 | C15: 429.75 | D15: 274.3 | E15: 717 | F15: 137.9 | G15: 93.98 | H15: 142.9 | I15: 142.15 | J15: 48.57 | K15: 106.49 | L15: 91.4 | M15: 50.49 | N15: 472.6 | O15: 24.48 | P15: 102.1 | Q15: 73.22 | R15: 12.81 | S15: 99.9 | T15: 35.13 | U15: 15.3 | V15: 30.59 | W15: 30.59 | X15: 13.06 | Y15: 31.57 | Z15: 73.26 | AA15: 599 | AB15: 169.15 | AD15: 27.89 | AE15: 117 | AG15: 2020 | AI15: =AVERAGE(G15,AA15,AE15) -> 269.99333 | AJ15: =AVERAGE(E15,Y15,AD15,G15,AA15,AE15) -> 264.40667 | AK15: =AVERAGE(Z15,V15,Q15,O15,M15,K15,H15,C15,E15,Y15,AD15,G15,AA15,AE15) -> 179.83 | AL15: =AVERAGE(AC15,AB15,X15,W15,U15,T15,S15,R15,P15,N15,L15,J15,I15,F15,D15,Z15,V15,Q15,O15,M15,K15,H15,C15,E15,Y15,AD15,G15,AA15,AE15) -> 148.66357 | AN15: 2020 | AO15: =(AI16-AI15)/AI15 -> -0.015099138 | AP15: =(AJ16-AJ15)/AJ15 -> -0.012606843 | AQ15: =(AK16-AK15)/AK15 -> -0.010136558 | AR15: =(AL16-AL15)/AL15 -> -0.010591989 | AS15: =(B16-B15)/B15 -> -0.012682893 | AU15: 2020 | AV15: =(AI15-AI14)/AI14 -> -0.013206306 | AW15: =(AJ15-AJ14)/AJ14 -> -0.011828607 | AX15: =(AK15-AK14)/AK14 -> -0.012465678 | AY15: =(AL15-AL14)/AL14 -> -0.0094590382 | AZ15: =(B15-B14)/B14 -> 0.00080444555
... A269: 267 | B269: 5563.74 | C269: 493.95 | D269: 298.4 | E269: 881 | F269: 92.55 | G269: 124.35 | H269: 124.05 | I269: 114.75 | J269: 37.1 | K269: 109.42 | L269: 81.09 | M269: 44.44 | N269: 436 | O269: 19.92 | P269: 84.72 | Q269: 53.62 | R269: 10.18 | S269: 76.44 | T269: 43.12 | U269: 13.62 | V269: 17.33 | W269: 17.33 | X269: 9.75 | Y269: 32.55 | Z269: 80 | AA269: 561.8 | AB269: 155.55 | AD269: 27.21 | AE269: 124.15 | AG269: 2021 | AI269: =AVERAGE(G269,AA269,AE269) -> 270.1 | AJ269: =AVERAGE(E269,Y269,AD269,G269,AA269,AE269) -> 291.84333 | AK269: =AVERAGE(Z269,V269,Q269,O269,M269,K269,H269,C269,E269,Y269,AD269,G269,AA269,AE269) -> 192.41357 | AL269: =AVERAGE(AC269,AB269,X269,W269,U269,T269,S269,R269,P269,N269,L269,J269,I269,F269,D269,Z269,V269,Q269,O269,M269,K269,H269,C269,E269,Y269,AD269,G269,AA269,AE269) -> 148.72821 | AN269: 2021 | AO269: =(AI270-AI269)/AI269 -> 0.0034555103 | AP269: =(AJ270-AJ269)/AJ269 -> 0.0051169006 | AQ269: =(AK270-AK269)/AK269 -> 0.0063924805 | AR269: =(AL270-AL269)/AL269 -> -0.028851102 | AS269: =(B270-B269)/B269 -> 0.0037474792 | AU269: 2021 | AV269: =(AI269-AI268)/AI268 -> -0.010381045 | AW269: =(AJ269-AJ268)/AJ268 -> -0.01407055 | AX269: =(AK269-AK268)/AK268 -> -0.015967123 | AY269: =(AL269-AL268)/AL268 -> -0.014326898 | AZ269: =(B269-B268)/B268 -> -0.016442303
A270: 268 | B270: 5584.59 | C270: 499.65 | D270: 296.9 | E270: 887.6 | F270: 91.19 | G270: 122.75 | H270: 125.05 | I270: 113.7 | J270: 36.98 | K270: 109.83 | L270: 81.19 | M270: 44.81 | N270: 436 | O270: 19.73 | P270: 84.66 | Q270: 54.72 | R270: 10.28 | S270: 75.46 | T270: 42.65 | U270: 13.49 | V270: 17.4 | W270: 17.4 | X270: 9.67 | Y270: 32.08 | Z270: 79.8 | AA270: 565.5 | AB270: 155.35 | AC270: 12.75 | AD270: 27.24 | AE270: 124.85 | AG270: 2021 | AI270: =AVERAGE(G270,AA270,AE270) -> 271.03333 | AJ270: =AVERAGE(E270,Y270,AD270,G270,AA270,AE270) -> 293.33667 | AK270: =AVERAGE(Z270,V270,Q270,O270,M270,K270,H270,C270,E270,Y270,AD270,G270,AA270,AE270) -> 193.64357 | AL270: =AVERAGE(AC270,AB270,X270,W270,U270,T270,S270,R270,P270,N270,L270,J270,I270,F270,D270,Z270,V270,Q270,O270,M270,K270,H270,C270,E270,Y270,AD270,G270,AA270,AE270) -> 144.43724 | AN270: 2021 | AO270: =(AI271-AI270)/AI270 -> -0.021092117 | AP270: =(AJ271-AJ270)/AJ270 -> -0.024232679 | AQ270: =(AK271-AK270)/AK270 -> -0.019745409 | AR270: =(AL271-AL270)/AL270 -> -0.0129277 | AS270: =(B271-B270)/B270 -> 0.0013626784 | AU270: 2021 | AV270: =(AI270-AI269)/AI269 -> 0.0034555103 | AW270: =(AJ270-AJ269)/AJ269 -> 0.0051169006 | AX270: =(AK270-AK269)/AK269 -> 0.0063924805 | AY270: =(AL270-AL269)/AL269 -> -0.028851102 | AZ270: =(B270-B269)/B269 -> 0.0037474792
A271: 269 | B271: 5592.2 | C271: 491.05 | D271: 297.1 | E271: 862.4 | F271: 91.3 | G271: 122.65 | H271: 123.1 | I271: 113.25 | J271: 37.15 | K271: 109.38 | L271: 82.78 | M271: 44.11 | N271: 432.6 | O271: 19.65 | P271: 84.84 | Q271: 56.18 | R271: 10.05 | S271: 75.6 | T271: 42.71 | U271: 13.58 | V271: 16.98 | W271: 16.98 | X271: 9.66 | Y271: 32.12 | Z271: 79.66 | AA271: 547.9 | AB271: 156.3 | AC271: 13.15 | AD271: 26.9 | AE271: 125.4 | AG271: 2021 | AI271: =AVERAGE(G271,AA271,AE271) -> 265.31667 | AJ271: =AVERAGE(E271,Y271,AD271,G271,AA271,AE271) -> 286.22833 | AK271: =AVERAGE(Z271,V271,Q271,O271,M271,K271,H271,C271,E271,Y271,AD271,G271,AA271,AE271) -> 189.82 | AL271: =AVERAGE(AC271,AB271,X271,W271,U271,T271,S271,R271,P271,N271,L271,J271,I271,F271,D271,Z271,V271,Q271,O271,M271,K271,H271,C271,E271,Y271,AD271,G271,AA271,AE271) -> 142.57 | AN271: 2021 | AO271: =(AI272-AI271)/AI271 -> 0.010616245 | AP271: =(AJ272-AJ271)/AJ271 -> 0.0089846684 | AQ271: =(AK272-AK271)/AK271 -> 0.012079113 | AR271: =(AL272-AL271)/AL271 -> 0.0095972214 | AS271: =(B272-B271)/B271 -> 0.0018400629 | AU271: 2021 | AV271: =(AI271-AI270)/AI270 -> -0.021092117 | AW271: =(AJ271-AJ270)/AJ270 -> -0.024232679 | AX271: =(AK271-AK270)/AK270 -> -0.019745409 | AY271: =(AL271-AL270)/AL270 -> -0.0129277 | AZ271: =(B271-B270)/B270 -> 0.0013626784
A272: 270 | B272: 5602.49 | C272: 507.7 | D272: 293.6 | E272: 868.2 | F272: 92.41 | G272: 123.2 | H272: 124.5 | I272: 114.9 | J272: 37.35 | K272: 108.26 | L272: 81.9 | M272: 44.42 | N272: 441.4 | O272: 19.72 | P272: 83.58 | Q272: 55.28 | R272: 10.21 | S272: 78.5 | T272: 43.25 | U272: 13.45 | V272: 17.08 | W272: 17.08 | X272: 9.66 | Y272: 32.45 | Z272: 79.82 | AA272: 556.7 | AB272: 154.15 | AC272: 13.19 | AD272: 27.75 | AE272: 124.5 | AG272: 2021 | AI272: =AVERAGE(G272,AA272,AE272) -> 268.13333 | AJ272: =AVERAGE(E272,Y272,AD272,G272,AA272,AE272) -> 288.8 | AK272: =AVERAGE(Z272,V272,Q272,O272,M272,K272,H272,C272,E272,Y272,AD272,G272,AA272,AE272) -> 192.11286 | AL272: =AVERAGE(AC272,AB272,X272,W272,U272,T272,S272,R272,P272,N272,L272,J272,I272,F272,D272,Z272,V272,Q272,O272,M272,K272,H272,C272,E272,Y272,AD272,G272,AA272,AE272) -> 143.93828 | AN272: 2021 | AO272: =(AI273-AI272)/AI272 -> -0.0059050224 | AP272: =(AJ273-AJ272)/AJ272 -> 0.0019390582 | AQ272: =(AK273-AK272)/AK272 -> 0.00047962879 | AR272: =(AL273-AL272)/AL272 -> -0.0011331485 | AS272: =(B273-B272)/B272 -> -0.0022650643 | AU272: 2021 | AV272: =(AI272-AI271)/AI271 -> 0.010616245 | AW272: =(AJ272-AJ271)/AJ271 -> 0.0089846684 | AX272: =(AK272-AK271)/AK271 -> 0.012079113 | AY272: =(AL272-AL271)/AL271 -> 0.0095972214 | AZ272: =(B272-B271)/B271 -> 0.0018400629
A273: 271 | B273: 5589.8 | C273: 507.6 | D273: 294.6 | E273: 875.6 | F273: 89.36 | G273: 125.15 | H273: 122.6 | I273: 111.95 | J273: 36.48 | K273: 108.39 | L273: 80.98 | M273: 44.34 | N273: 447.4 | O273: 19.52 | P273: 81.52 | Q273: 55.08 | R273: 10.06 | S273: 76.58 | T273: 43.32 | U273: 13.32 | V273: 16.9 | W273: 16.9 | X273: 9.56 | Y273: 32.85 | Z273: 80.28 | AA273: 550.2 | AB273: 153.65 | AC273: 12.93 | AD273: 28.06 | AE273: 124.3 | AG273: 2021 | AI273: =AVERAGE(G273,AA273,AE273) -> 266.55 | AJ273: =AVERAGE(E273,Y273,AD273,G273,AA273,AE273) -> 289.36 | AK273: =AVERAGE(Z273,V273,Q273,O273,M273,K273,H273,C273,E273,Y273,AD273,G273,AA273,AE273) -> 192.205 | AL273: =AVERAGE(AC273,AB273,X273,W273,U273,T273,S273,R273,P273,N273,L273,J273,I273,F273,D273,Z273,V273,Q273,O273,M273,K273,H273,C273,E273,Y273,AD273,G273,AA273,AE273) -> 143.77517 | AN273: 2021 | AO273: =(AI274-AI273)/AI273 -> -0.0086287751 | AP273: =(AJ274-AJ273)/AJ273 -> -0.0040030873 | AQ273: =(AK274-AK273)/AK273 -> -0.0020402323 | AR273: =(AL274-AL273)/AL273 -> -0.0028372843 | AS273: =(B274-B273)/B273 -> -0.014018391 | AU273: 2021 | AV273: =(AI273-AI272)/AI272 -> -0.0059050224 | AW273: =(AJ273-AJ272)/AJ272 -> 0.0019390582 | AX273: =(AK273-AK272)/AK272 -> 0.00047962879 | AY273: =(AL273-AL272)/AL272 -> -0.0011331485 | AZ273: =(B273-B272)/B272 -> -0.0022650643
A274: 272 | B274: 5511.44 | C274: 511.5 | D274: 296.3 | E274: 875.6 | F274: 88.83 | G274: 125.35 | H274: 122.5 | I274: 110.55 | J274: 36.22 | K274: 109.13 | L274: 81.02 | M274: 43.09 | N274: 446.2 | O274: 19.21 | P274: 80.46 | Q274: 54.56 | R274: 9.92 | S274: 75.5 | T274: 42.6 | U274: 13.12 | V274: 16.34 | W274: 16.34 | X274: 9.59 | Y274: 33 | Z274: 79.84 | AA274: 544 | AB274: 153.1 | AC274: 12.52 | AD274: 27.86 | AE274: 123.4 | AG274: 2021 | AI274: =AVERAGE(G274,AA274,AE274) -> 264.25 | AJ274: =AVERAGE(E274,Y274,AD274,G274,AA274,AE274) -> 288.20167 | AK274: =AVERAGE(Z274,V274,Q274,O274,M274,K274,H274,C274,E274,Y274,AD274,G274,AA274,AE274) -> 191.81286 | AL274: =AVERAGE(AC274,AB274,X274,W274,U274,T274,S274,R274,P274,N274,L274,J274,I274,F274,D274,Z274,V274,Q274,O274,M274,K274,H274,C274,E274,Y274,AD274,G274,AA274,AE274) -> 143.36724 | AN274: 2021 | AO274: =(AI275-AI274)/AI274 -> -0.017470829 | AP274: =(AJ275-AJ274)/AJ274 -> -0.011415618 | AQ274: =(AK275-AK274)/AK274 -> -0.013346342 | AR274: =(AL275-AL274)/AL274 -> -0.013377749 | AS274: =(B275-B274)/B274 -> -0.010559854 | AU274: 2021 | AV274: =(AI274-AI273)/AI273 -> -0.0086287751 | AW274: =(AJ274-AJ273)/AJ273 -> -0.0040030873 | AX274: =(AK274-AK273)/AK273 -> -0.0020402323 | AY274: =(AL274-AL273)/AL273 -> -0.0028372843 | AZ274: =(B274-B273)/B273 -> -0.014018391
A275: 273 | B275: 5453.24 | C275: 501.9 | D275: 299 | E275: 869.6 | F275: 84.87 | G275: 124.7 | H275: 120.55 | I275: 106.15 | J275: 35.35 | K275: 108.6 | L275: 81.06 | M275: 41.23 | N275: 440.6 | O275: 18.77 | P275: 78.72 | Q275: 54.7 | R275: 9.5 | S275: 73.2 | T275: 42.03 | U275: 12.93 | V275: 15.62 | W275: 15.62 | X275: 9.55 | Y275: 33.53 | Z275: 78.7 | AA275: 533 | AB275: 151.95 | AC275: 11.96 | AD275: 27.44 | AE275: 121.2 | AG275: 2021 | AI275: =AVERAGE(G275,AA275,AE275) -> 259.63333 | AJ275: =AVERAGE(E275,Y275,AD275,G275,AA275,AE275) -> 284.91167 | AK275: =AVERAGE(Z275,V275,Q275,O275,M275,K275,H275,C275,E275,Y275,AD275,G275,AA275,AE275) -> 189.25286 | AL275: =AVERAGE(AC275,AB275,X275,W275,U275,T275,S275,R275,P275,N275,L275,J275,I275,F275,D275,Z275,V275,Q275,O275,M275,K275,H275,C275,E275,Y275,AD275,G275,AA275,AE275) -> 141.44931 | AN275: 2021 | AO275: =(AI276-AI275)/AI275 -> 0.018102452 | AP275: =(AJ276-AJ275)/AJ275 -> 0.0089267434 | AQ275: =(AK276-AK275)/AK275 -> 0.01028103 | AR275: =(AL276-AL275)/AL275 -> 0.0093514674 | AS275: =(B276-B275)/B275 -> 0.0032732834 | AU275: 2021 | AV275: =(AI275-AI274)/AI274 -> -0.017470829 | AW275: =(AJ275-AJ274)/AJ274 -> -0.011415618 | AX275: =(AK275-AK274)/AK274 -> -0.013346342 | AY275: =(AL275-AL274)/AL274 -> -0.013377749 | AZ275: =(B275-B274)/B274 -> -0.010559854
A276: 274 | B276: 5471.09 | C276: 508 | D276: 301.8 | E276: 870 | F276: 85.29 | G276: 125.6 | H276: 120.7 | I276: 108 | J276: 35.98 | K276: 111.53 | L276: 80.63 | M276: 41.99 | N276: 444.2 | O276: 18.86 | P276: 77.98 | Q276: 55.38 | R276: 9.67 | S276: 73.36 | T276: 41.94 | U276: 12.99 | V276: 15.99 | W276: 15.99 | X276: 9.7 | Y276: 33.94 | Z276: 79.6 | AA276: 545.7 | AB276: 153.9 | AC276: 12.18 | AD276: 27.79 | AE276: 121.7 | AG276: 2021 | AI276: =AVERAGE(G276,AA276,AE276) -> 264.33333 | AJ276: =AVERAGE(E276,Y276,AD276,G276,AA276,AE276) -> 287.455 | AK276: =AVERAGE(Z276,V276,Q276,O276,M276,K276,H276,C276,E276,Y276,AD276,G276,AA276,AE276) -> 191.19857 | AL276: =AVERAGE(AC276,AB276,X276,W276,U276,T276,S276,R276,P276,N276,L276,J276,I276,F276,D276,Z276,V276,Q276,O276,M276,K276,H276,C276,E276,Y276,AD276,G276,AA276,AE276) -> 142.77207 | AN276: 2021 | AO276: =(AI277-AI276)/AI276 -> -0.0110971 | AP276: =(AJ277-AJ276)/AJ276 -> -0.014709549 | AQ276: =(AK277-AK276)/AK276 -> -0.011887417 | AR276: =(AL277-AL276)/AL276 -> -0.012131707 | AS276: =(B277-B276)/B276 -> -0.012732381 | AU276: 2021 | AV276: =(AI276-AI275)/AI275 -> 0.018102452 | AW276: =(AJ276-AJ275)/AJ275 -> 0.0089267434 | AX276: =(AK276-AK275)/AK275 -> 0.01028103 | AY276: =(AL276-AL275)/AL275 -> 0.0093514674 | AZ276: =(B276-B275)/B275 -> 0.0032732834
A277: 275 | B277: 5401.43 | C277: 506.4 | D277: 297.6 | E277: 854.2 | F277: 84.36 | G277: 123.1 | H277: 118.35 | I277: 105.95 | J277: 35.83 | K277: 112.81 | L277: 78.64 | M277: 40.53 | N277: 438.6 | O277: 18.67 | P277: 76.84 | Q277: 55.2 | R277: 9.43 | S277: 74.28 | T277: 40.82 | U277: 12.73 | V277: 15.56 | W277: 15.56 | X277: 9.85 | Y277: 33.83 | Z277: 78.08 | AA277: 541.6 | AB277: 152.95 | AC277: 11.76 | AD277: 27.13 | AE277: 119.5 | AG277: 2021 | AI277: =AVERAGE(G277,AA277,AE277) -> 261.4 | AJ277: =AVERAGE(E277,Y277,AD277,G277,AA277,AE277) -> 283.22667 | AK277: =AVERAGE(Z277,V277,Q277,O277,M277,K277,H277,C277,E277,Y277,AD277,G277,AA277,AE277) -> 188.92571 | AL277: =AVERAGE(AC277,AB277,X277,W277,U277,T277,S277,R277,P277,N277,L277,J277,I277,F277,D277,Z277,V277,Q277,O277,M277,K277,H277,C277,E277,Y277,AD277,G277,AA277,AE277) -> 141.04 | AN277: 2021 | AO277: =(AI278-AI277)/AI277 -> 0.019127774 | AP277: =(AJ278-AJ277)/AJ277 -> 0.013134356 | AQ277: =(AK278-AK277)/AK277 -> 0.012540832 | AR277: =(AL278-AL277)/AL277 -> 0.011627907 | AS277: =(B278-B277)/B277 -> -0.0041118741 | AU277: 2021 | AV277: =(AI277-AI276)/AI276 -> -0.0110971 | AW277: =(AJ277-AJ276)/AJ276 -> -0.014709549 | AX277: =(AK277-AK276)/AK276 -> -0.011887417 | AY277: =(AL277-AL276)/AL276 -> -0.012131707 | AZ277: =(B277-B276)/B276 -> -0.012732381
A278: 276 | B278: 5379.22 | C278: 517 | D278: 297.4 | E278: 861.6 | F278: 85.15 | G278: 123.8 | H278: 117.9 | I278: 106.3 | J278: 35.82 | K278: 112.73 | L278: 78.66 | M278: 41.21 | N278: 444 | O278: 18.8 | P278: 78.68 | Q278: 55.28 | R278: 9.57 | S278: 73.98 | T278: 41.61 | U278: 12.96 | V278: 15.77 | W278: 15.77 | X278: 9.8 | Y278: 33.17 | Z278: 77.76 | AA278: 555.9 | AB278: 157.85 | AC278: 12.04 | AD278: 27.71 | AE278: 119.5 | AG278: 2021 | AI278: =AVERAGE(G278,AA278,AE278) -> 266.4 | AJ278: =AVERAGE(E278,Y278,AD278,G278,AA278,AE278) -> 286.94667 | AK278: =AVERAGE(Z278,V278,Q278,O278,M278,K278,H278,C278,E278,Y278,AD278,G278,AA278,AE278) -> 191.295 | AL278: =AVERAGE(AC278,AB278,X278,W278,U278,T278,S278,R278,P278,N278,L278,J278,I278,F278,D278,Z278,V278,Q278,O278,M278,K278,H278,C278,E278,Y278,AD278,G278,AA278,AE278) -> 142.68 | AN278: 2021 | AO278: =(AI279-AI278)/AI278 -> -0.021458959 | AP278: =(AJ279-AJ278)/AJ278 -> -0.020677478 | AQ278: =(AK279-AK278)/AK278 -> -0.022702408 | AR278: =(AL279-AL278)/AL278 -> -0.02262357 | AS278: =(B279-B278)/B278 -> 0.0037161522 | AU278: 2021 | AV278: =(AI278-AI277)/AI277 -> 0.019127774 | AW278: =(AJ278-AJ277)/AJ277 -> 0.013134356 | AX278: =(AK278-AK277)/AK277 -> 0.012540832 | AY278: =(AL278-AL277)/AL277 -> 0.011627907 | AZ278: =(B278-B277)/B277 -> -0.0041118741
A279: 277 | B279: 5399.21 | C279: 498.3 | D279: 290.1 | E279: 842.6 | F279: 83.2 | G279: 120.95 | H279: 117 | I279: 104.1 | J279: 34.9 | K279: 111.57 | L279: 76.73 | M279: 39.78 | N279: 431 | O279: 18.3 | P279: 76.58 | Q279: 54.96 | R279: 9.38 | S279: 74.18 | T279: 41.08 | U279: 12.82 | V279: 15.44 | W279: 15.44 | X279: 9.7 | Y279: 32.95 | Z279: 75.9 | AA279: 541.6 | AB279: 155.7 | AC279: 11.87 | AD279: 28.48 | AE279: 119.5 | AG279: 2021 | AI279: =AVERAGE(G279,AA279,AE279) -> 260.68333 | AJ279: =AVERAGE(E279,Y279,AD279,G279,AA279,AE279) -> 281.01333 | AK279: =AVERAGE(Z279,V279,Q279,O279,M279,K279,H279,C279,E279,Y279,AD279,G279,AA279,AE279) -> 186.95214 | AL279: =AVERAGE(AC279,AB279,X279,W279,U279,T279,S279,R279,P279,N279,L279,J279,I279,F279,D279,Z279,V279,Q279,O279,M279,K279,H279,C279,E279,Y279,AD279,G279,AA279,AE279) -> 139.45207 | AN279: 2021 | AO279: =(AI280-AI279)/AI279 -> 0.0084393581 | AP279: =(AJ280-AJ279)/AJ279 -> 0.01119164 | AQ279: =(AK280-AK279)/AK279 -> 0.013276889 | AR279: =(AL280-AL279)/AL279 -> 0.014230572 | AS279: =(B280-B279)/B279 -> 0.0056619394 | AU279: 2021 | AV279: =(AI279-AI278)/AI278 -> -0.021458959 | AW279: =(AJ279-AJ278)/AJ278 -> -0.020677478 | AX279: =(AK279-AK278)/AK278 -> -0.022702408 | AY279: =(AL279-AL278)/AL278 -> -0.02262357 | AZ279: =(B279-B278)/B278 -> 0.0037161522
A280: 278 | B280: 5429.78 | C280: 507.7 | D280: 296.5 | E280: 854.2 | F280: 83.11 | G280: 123.4 | H280: 120.5 | I280: 102.95 | J280: 34.56 | K280: 112.48 | L280: 77.79 | M280: 40.18 | N280: 443.8 | O280: 18.45 | P280: 77.92 | Q280: 55.6 | R280: 9.52 | S280: 74.6 | T280: 41.64 | U280: 12.98 | V280: 15.58 | W280: 15.58 | X280: 9.73 | Y280: 33.55 | Z280: 76.64 | AA280: 543 | AB280: 156.95 | AC280: 11.95 | AD280: 28.55 | AE280: 122.25 | AG280: 2021 | AI280: =AVERAGE(G280,AA280,AE280) -> 262.88333 | AJ280: =AVERAGE(E280,Y280,AD280,G280,AA280,AE280) -> 284.15833 | AK280: =AVERAGE(Z280,V280,Q280,O280,M280,K280,H280,C280,E280,Y280,AD280,G280,AA280,AE280) -> 189.43429 | AL280: =AVERAGE(AC280,AB280,X280,W280,U280,T280,S280,R280,P280,N280,L280,J280,I280,F280,D280,Z280,V280,Q280,O280,M280,K280,H280,C280,E280,Y280,AD280,G280,AA280,AE280) -> 141.43655 | AN280: 2021 | AO280: =(AI281-AI280)/AI280 -> 0.014201484 | AP280: =(AJ281-AJ280)/AJ280 -> 0.024962609 | AQ280: =(AK281-AK280)/AK280 -> 0.024305451 | AR280: =(AL281-AL280)/AL280 -> 0.023285694 | AS280: =(B281-B280)/B280 -> 0.01463411 | AU280: 2021 | AV280: =(AI280-AI279)/AI279 -> 0.0084393581 | AW280: =(AJ280-AJ279)/AJ279 -> 0.01119164 | AX280: =(AK280-AK279)/AK279 -> 0.013276889 | AY280: =(AL280-AL279)/AL279 -> 0.014230572 | AZ280: =(B280-B279)/B279 -> 0.0056619394
A281: 279 | B281: 5509.24 | C281: 524.9 | D281: 298.4 | E281: 884.8 | F281: 88.59 | G281: 125.9 | H281: 123.05 | I281: 107.85 | J281: 34.87 | K281: 112.27 | L281: 78.17 | M281: 41.61 | N281: 453 | O281: 18.82 | P281: 80.16 | Q281: 54.68 | R281: 9.8 | S281: 76.84 | T281: 42.05 | U281: 13.04 | V281: 16.14 | W281: 16.14 | X281: 9.72 | Y281: 34.25 | Z281: 77.56 | AA281: 549.2 | AB281: 159.7 | AC281: 12.3 | AD281: 28.61 | AE281: 124.75 | AG281: 2021 | AI281: =AVERAGE(G281,AA281,AE281) -> 266.61667 | AJ281: =AVERAGE(E281,Y281,AD281,G281,AA281,AE281) -> 291.25167 | AK281: =AVERAGE(Z281,V281,Q281,O281,M281,K281,H281,C281,E281,Y281,AD281,G281,AA281,AE281) -> 194.03857 | AL281: =AVERAGE(AC281,AB281,X281,W281,U281,T281,S281,R281,P281,N281,L281,J281,I281,F281,D281,Z281,V281,Q281,O281,M281,K281,H281,C281,E281,Y281,AD281,G281,AA281,AE281) -> 144.73 | AN281: 2021 | AO281: =(AI282-AI281)/AI281 -> -0.0081890354 | AP281: =(AJ282-AJ281)/AJ281 -> -0.0002460644 | AQ281: =(AK282-AK281)/AK281 -> -0.00053008607 | AR281: =(AL282-AL281)/AL281 -> -0.0017893009 | AS281: =(B282-B281)/B281 -> 0.0081408688 | AU281: 2021 | AV281: =(AI281-AI280)/AI280 -> 0.014201484 | AW281: =(AJ281-AJ280)/AJ280 -> 0.024962609 | AX281: =(AK281-AK280)/AK280 -> 0.024305451 | AY281: =(AL281-AL280)/AL280 -> 0.023285694 | AZ281: =(B281-B280)/B280 -> 0.01463411
